Workbook

Sheet README
A1: LLM chatbots & dental patient information – systematic review workbook
A3: Title | B3: Accuracy and Safety-Related Limitations of General-Purpose LLM Chatbots for Dental Patient Information: A Systematic Review Across Specialties
A4: Version / date | B4: v1.1 – 2026-10-08 (title/abstract stage completed)
A5: Search date | B5: 2026-10-02 (period 2022-01-01 to 2026-10-02)
A6: Source file | B6: 20261008_LLM_Dental_SR_Raw_Records_before_Deduplication_2026-10-02.xlsx (7,734 raw records, deduplication groups)
A8: Sheet | B8: Content
A9: PICOS_Eligibility | B9: Review questions, PICOS, exclusion reason codes (TA E1–E5, FT FT1–FT8)
A10: Reviewer_Team | B10: Roles and dental backgrounds of R1, R2, R3
A11: Search_Sources | B11: Information sources, search IDs, strategies, record counts (PRISMA-S)
A12: NL_Queries | B12: Natural-language queries used with AI search connectors
A13: PRISMA_Flow | B13: PRISMA 2020 flow numbers (TA stage = live formulas on TA_Screening; FT stage = formulas on FT_Screening)
A14: TA_Screening | B14: Screening sheet: all records with R1/R2 decisions, R3 arbitration, ASReview score/QC, final decision; yellow columns for human validation
A15: Agreement | B15: Inter-reviewer agreement and Cohen's κ per batch and overall
... A30: Legend | B30: Yellow cells = input cells for the team. Grey italic rows = example row showing expected format (delete or overwrite). Dark-blue header rows = fixed.

Sheet PICOS_Eligibility
A1: Review questions and eligibility criteria (PICOS)
A3: Primary question | B3: How accurate is patient-facing dental health information generated by general-purpose large language model chatbots, and what potentially harmful errors or safety-relevant omissions are reported across dental specialties?
A4: Secondary question | B4: To what extent do reported accuracy and safety-related outcomes differ across dental specialties, and how are these differences associated with model version, task characteristics, and evaluation methods?
A6: Element | B6: Definition for this review | C6: Operationalisation / notes
A7: P – Population (information need) | B7: Dental, oral and maxillofacial health information needs of patients, parents/caregivers and the lay public, in any dental specialty. | C7: Patient FAQs, patient-style questions, lay scenarios (e.g. dental trauma first aid), patient education topics. Specialties coded a priori: OMFS/dentoalveolar surgery, orthodontics, endodontics, periodontology, prosthodontics, implantology, paediatric dentistry, restorative dentistry/cariology, oral medicine/pathology incl. oral cancer, TMD/orofacial pain, dental trauma, preventive/community oral health, oral radiology, cleft lip/palate, dental sleep medicine, multi-specialty/general dentistry.
A8: I – Index technology | B8: General-purpose, publicly available LLM chatbots used as released (web interface, app or API). | C8: ChatGPT (GPT-3.5, GPT-4, GPT-4o, o-series, GPT-5), Gemini/Bard, Microsoft Copilot/Bing Chat, Claude, Llama/Meta AI, Perplexity, DeepSeek, Mistral/Le Chat, Grok, ERNIE Bot, Qwen and comparable systems. Custom GPTs, RAG or fine-tuned models are eligible comparators but only general-purpose arms enter the primary synthesis.
A9: C – Comparator | B9: Not required. | C9: If present: other LLMs/versions, dentists/specialists, professional websites, guidelines, search engines.
A10: O – Outcomes | B10: Primary: accuracy (correctness) of LLM-generated content; potentially harmful errors; safety-relevant omissions. | C10: Secondary: completeness, overall/content quality (GQS, DISCERN, EQIP), guideline concordance, readability (FRE, FKGL, SMOG), understandability/actionability (PEMAT), consistency/reproducibility, empathy, inter-rater reliability. A study must report ≥1 primary outcome (accuracy or a safety outcome) to be included.
A11: S – Study design | B11: Primary empirical evaluation studies (cross-sectional/in-silico, comparative or observational) with original data. | C11: Full articles and research letters/short communications with original data in peer-reviewed journals. Excluded: reviews, editorials, commentaries, letters without data, protocols, conference abstracts, book chapters, errata, questionnaire surveys of perceptions.
A12: Timeframe / language | B12: Published 1 January 2022 – 2 October 2026 (de facto from the release of ChatGPT, 30 November 2022). | C12: No restriction on the language of the chatbot query. Full texts in English or German assessed directly; other languages via verified machine translation.
A15: Code | B15: Title/abstract stage (TA) | C15: Full-text stage (FT)
A16: E1 / FT1 | B16: Not a dental, oral or maxillofacial topic | C16: Not a dental, oral or maxillofacial topic
A17: E2 / FT2 | B17: Not a general-purpose LLM chatbot (other AI, rule-based bot, only domain-specific model) | C17: No extractable general-purpose LLM arm
A18: E3 / FT3 | B18: Not patient-facing (exam/MCQ, professional decision support, image diagnosis, education, research use) | C18: Patient-facing subset not identifiable or not separately reported
A19: E4 / FT4 | B19: No content evaluation of LLM output (e.g. readability only, perceptions survey) | C19: No accuracy or safety outcome reported (or not extractable)
... A35: S9 | B35: Inconsistency with safety impact | C35: Contradictory advice across repetitions or model versions

Sheet Reviewer_Team
A1: Reviewer team
A3: Role | B3: Reviewer profile (dental background) | C3: Task
A4: Reviewer 1 (R1) | B4: Oral and maxillofacial surgeon (DMD, MD); dentoalveolar and implant surgery, oral oncology, TMJ; research on patient information and informed consent | C4: Independent title/abstract screening of all records (calibration + main round)
A5: Reviewer 2 (R2) | B5: Orthodontist and paediatric dentist (DDS, MSc) with postgraduate training in dental public health; research on oral-health literacy, readability and quality of online patient information (DISCERN, PEMAT) | C5: Independent title/abstract screening of all records (calibration + main round)
A6: Reviewer 3 (R3) | B6: Periodontist and restorative dentist; senior evidence-based-dentistry methodologist (systematic review and GRADE experience) | C6: Arbitration of all conflicts and UNSURE records; safety re-check of records flagged by the ASReview quality control

Sheet Search_Sources
A1: Information sources and search strategies (PRISMA-S)
A3: Source | B3: Search ID | C3: Strategy (see note) | D3: Records retrieved | E3: Date searched | F3: Date limits | G3: Other limits
A4: PubMed/MEDLINE | B4: PM-01 | C4: C1 AND C2 in [tiab]/MeSH; 2022/01/01:2026/10/02[dp]. Reconstructed logic: (ChatGPT OR "large language model" OR chatbot OR "generative AI" OR GPT-4 OR Gemini OR Bard OR Copilot OR Claude OR DeepSeek OR Llama OR Perplexity)[tiab] AND (dental OR dentistry OR dentist OR "oral health" OR orthodontic OR endodontic OR periodontal OR prosthodontic OR "oral surgery" OR maxillofacial OR "dental implant" OR "pediatric dentistry" OR caries OR teeth)[tiab] – verify verbatim string | D4: 1315 | E4: 2026-10-02 | F4: 2022-01-01 – 2026-10-02 | G4: none
A5: Europe PMC (+ preprints) | B5: EP-01 | C5: C1 AND C2 (TITLE_ABS/KW); FIRST_PDATE:[2022-01-01 TO 2026-10-02]; SRC incl. PPR | D5: 1400 | E5: 2026-10-02 | F5: 2022-01-01 – 2026-10-02 | G5: none
A6: Semantic Scholar | B6: S2-01 | C6: C1 AND C2 (title/abstract), year 2022–2026 | D6: 1903 | E6: 2026-10-02 | F6: 2022-01-01 – 2026-10-02 | G6: none
A7: Crossref | B7: CR-01..CR-120 | C7: 120 pairwise C1 term × C2 term queries (query.bibliographic), from-pub-date 2022-01-01; local filter C1∧C2 in title/abstract/keywords | D7: 694 | E7: 2026-10-02 | F7: 2022-01-01 – 2026-10-02 | G7: none
A8: DOAJ | B8: DJ-01 | C8: C1 AND C2 (bibjson.title/abstract/keywords), 2022–2026 | D8: 1018 | E8: 2026-10-02 | F8: 2022-01-01 – 2026-10-02 | G8: none
A9: arXiv | B9: AX-01 | C9: all: C1 AND C2, submittedDate 2022–2026 | D9: 54 | E9: 2026-10-02 | F9: 2022-01-01 – 2026-10-02 | G9: none
A10: Amass BiomedCore | B10: AM01, AM02, Q01–Q15 | C10: AM01: (ChatGPT OR "large language model" OR chatbot OR "generative AI" OR GPT-4 OR Gemini OR Bard OR Copilot OR Claude OR DeepSeek OR Llama OR Perplexity) AND (dental OR dentistry OR dentist OR "oral health" OR orthodontic OR endodontic OR periodontal OR prosthodontic OR "oral surgery" OR maxillofacial OR "dental implant" OR "pediatric dentistry" OR caries OR teeth); AM02 focused (see S1a); Q01–Q15 natural language | D10: 850 | E10: 2026-10-02 | F10: 2022-01-01 – 2026-10-02 | G10: none
A11: Wiley Scholar Gateway | B11: Q01–Q15 | C11: Natural-language full-text queries (S1c); passages mapped to articles | D11: 300 | E11: 2026-10-02 | F11: 2022-01-01 – 2026-10-02 | G11: none
A12: Consensus | B12: Q01–Q20 | C12: Natural-language queries (S1c); first author only, matched by title | D12: 200 | E12: 2026-10-02 | F12: 2022-01-01 – 2026-10-02 | G12: none
A13: Elicit | B13: – | C13: Q01–Q20 attempted; refused (no API access) | D13: 0 | E13: 2026-10-02 | F13: 2022-01-01 – 2026-10-02 | G13: none
C14: Total | D14: =SUM(D4:D13) -> 7734
A16: Concept block C1 (LLM/chatbot): (ChatGPT OR "large language model" OR chatbot OR "generative AI" OR GPT-4 OR Gemini OR Bard OR Copilot OR Claude OR DeepSeek OR Llama OR Perplexity)
A17: Concept block C2 (dentistry): (dental OR dentistry OR dentist OR "oral health" OR orthodontic OR endodontic OR periodontal OR prosthodontic OR "oral surgery" OR maxillofacial OR "dental implant" OR "pediatric dentistry" OR caries OR teeth)
A18: Verbatim database syntax is stored in sheet Search_Strategy of LLM_Dental_SR_Search_Results_2026-10-02.xlsx – paste here before submission.
A19: Pending complementary searches: Scopus, Web of Science Core Collection, Embase, IEEE Xplore, Google Scholar (first 200), backward/forward citation searching.
A22: Source | B22: Raw records | C22: Retained as primary record | D22: Removed as duplicate | E22: Raw records in screening-set groups
A23: Amass BiomedCore (connector) | B23: 850 | C23: 373 | D23: 477 | E23: 459
A24: Consensus (connector) | B24: 200 | C24: 11 | D24: 189 | E24: 192
A25: Crossref | B25: 694 | C25: 228 | D25: 466 | E25: 669
A26: DOAJ | B26: 1018 | C26: 456 | D26: 562 | E26: 596
A27: Europe PMC | B27: 1294 | C27: 2 | D27: 1292 | E27: 1294
A28: Europe PMC (Preprint) | B28: 106 | C28: 82 | D28: 24 | E28: 106
A29: PubMed/MEDLINE | B29: 1315 | C29: 1315 | D29: 0 | E29: 1315
A30: Semantic Scholar | B30: 1903 | C30: 520 | D30: 1383 | E30: 1903
A31: Wiley Scholar Gateway (connector, full text) | B31: 300 | C31: 57 | D31: 243 | E31: 218
A32: arXiv | B32: 54 | C32: 11 | D32: 43 | E32: 43

Sheet NL_Queries
A1: Natural-language queries (semantic connectors)
A3: ID | B3: Query | C3: Connectors
A4: Q01 | B4: accuracy of ChatGPT responses to dental patient questions | C4: Consensus; Amass; Wiley
A5: Q02 | B5: large language model chatbots patient information dentistry accuracy and safety | C5: Consensus; Amass; Wiley
A6: Q03 | B6: ChatGPT orthodontics patient questions accuracy | C6: Consensus; Amass; Wiley
A7: Q04 | B7: chatbot endodontics root canal treatment patient information quality | C7: Consensus; Amass; Wiley
A8: Q05 | B8: large language model periodontology periodontal disease patient education | C8: Consensus; Amass; Wiley
A9: Q06 | B9: ChatGPT oral and maxillofacial surgery third molar extraction patient information | C9: Consensus; Amass; Wiley
A10: Q07 | B10: chatbot pediatric dentistry parents questions accuracy | C10: Consensus; Amass; Wiley
A11: Q08 | B11: large language model dental implants patient questions | C11: Consensus; Amass; Wiley
A12: Q09 | B12: ChatGPT prosthodontics dentures patient information | C12: Consensus; Amass; Wiley
A13: Q10 | B13: Gemini Bard Copilot chatbots comparison dental questions | C13: Consensus; Amass; Wiley
A14: Q11 | B14: readability and reliability of AI chatbot responses about oral health | C14: Consensus; Amass; Wiley
... A23: Q20 | B23: large language model cleft lip palate patient information | C23: Consensus

Sheet TA_Screening
A1: Record ID | B1: Screening order | C1: Batch | D1: Title | E1: Abstract | F1: Authors | G1: Year | H1: Journal | I1: DOI | J1: PMID | K1: Publication type | L1: Language | M1: Specialty flag (rule-based) | N1: Sources | O1: R1 decision | P1: R1 code | Q1: R1 note | R1: R2 decision | S1: R2 code | T1: R2 note | U1: R1/R2 agreement | V1: R3 decision | W1: R3 code | X1: R3 rationale | Y1: ASReview OOF score | Z1: ASReview rank | AA1: QC flag | AB1: QC R3 decision | AC1: QC R3 rationale | AD1: Final TA decision | AE1: Final exclusion code | AF1: Decision basis | AG1: Human validation (Agree/Disagree) | AH1: Human validator | AI1: Validation comment
A2: LLMDENT-1819 | B2: 1 | C2: calibration | D2: Is the field of endodontics prepared to utilise ChatGPT? | F2: Maltarollo, Thalya Fernanda Horsth; Strazzi-Sahyon, Henrico Badaoui; Amaral, Rodrigo Rodrigues; Sivieri-Araújo, Gustavo | G2: 2024 | H2: Australian endodontic journal : the journal of the Australian Society of Endodontology Inc | I2: 10.1111/aej.12821 | J2: 37994592.0 | K2: Letter / comment / editorial | L2: English | M2: Endodontics | N2: Crossref; Europe PMC; PubMed/MEDLINE; Semantic Scholar | O2: EXCLUDE | P2: E5 | Q2: letter/comment on ChatGPT in endodontics; no abstract; no data apparent | R2: EXCLUDE | S2: E5 | T2: letter/comment no abstract; no evaluation data indicated | U2: =IF(AND(O2=R2,O2<>"UNSURE"),"Agree","Conflict/Unsure") -> Agree | Y2: 0.145 | Z2: 1526 | AA2: No | AD2: EXCLUDE | AE2: E5 | AF2: R1 = R2
A3: LLMDENT-2095 | B3: 2 | C3: calibration | D3: Role of Dental Pulp Stem Cells to Promote Angiogenesis in Cell-based Regenerative Endodontics. | E3: Maintaining the viability and avoiding necrosis of dental pulp are crucial to preserving the structural integrity and functioning of teeth. In recent years, cell-based regenerative endodontics has emerged as a promising approach to achieve this goal and has gained increasing attention in scientific research; however, in the confined space of the root canal system, hypoxic conditions can be both beneficial and detrimental, as they may promote angiogenesis in the graft to some extent but also lead to tissue necrosis if prolonged. Dental pulp stem cells (DPSCs) have been verified as multipotent cells that can promote angiogenesis and are therefore ideal candidates for realising real dental pulp regeneration within root canals. Thus, we focus on the underlying mechanisms of DPSCs to promote angiogenesis and summarise some preclinical studies and clinical trials involving transplanting of DPSCs to achieve real dental pulp regeneration, in the hope that this intractable source of perplexity in regenerative endodontics may be resolved sooner. | F3: Tang, Meng Qi; Ye, Ling; Gao, Bo | G3: 2023 | H3: The Chinese journal of dental research | I3: 10.3290/j.cjdr.b4330823 | J3: 37732679.0 | K3: Journal article (original research) | L3: English | M3: Endodontics | N3: Europe PMC; PubMed/MEDLINE; Semantic Scholar | O3: EXCLUDE | P3: E2 | Q3: dental pulp stem cells; no LLM | R3: EXCLUDE | S3: E2 | T3: dental pulp stem cells review; no LLM | U3: =IF(AND(O3=R3,O3<>"UNSURE"),"Agree","Conflict/Unsure") -> Agree | Y3: 0.05 | Z3: 1971 | AA3: No | AD3: EXCLUDE | AE3: E2 | AF3: R1 = R2
A4: LLMDENT-1762 | B4: 3 | C4: calibration | D4: Hygiea+: Toward Energy-Efficient and Highly Accurate Toothbrushing Monitoring via Wrist-Worn Gesture Sensing | E4: Proper and effective toothbrushing technique is crucial for maintaining oral health. However, there are often limited opportunities for individuals to receive specific training in toothbrushing posture in their daily lives. In this article, we propose Hygiea+, a convenient, energy-efficient, and highly accurate toothbrushing monitoring system based on wrist-worn wearables. By leveraging inertial measurement units (IMUs) in wrist-worn devices for gesture sensing, Hygiea+ enables users to accurately and efficiently monitor their toothbrushing activities without any modifications to the toothbrush. We propose a number of novel techniques to achieve the goal of high sensing accuracy and energy efficiency. To reduce the energy consumption of continuous IMU sampling, we model the sensing problem as a Markov process and design a partially observable Markov decision process (POMDP)-based adaptive sampling strategy to dynamically adjust the sampling frequency. To achieve high sensing accuracy, we first propose a novel signal preprocessing method to mitigate variations resulting from different toothbrush types and user habits. Then, we propose a deep reinforcement learning-based data distillation mechanism to extract key segments from continuous toothbrushing actions, thus reducing the impact of redundant data and noise. In the classification stage, we design an attention-based long short-term memory (AT-LSTM) network for fine-grained toothbrushing posture recognition. In addition, to … | F4: Xingyu Feng; Chengwen Luo; Junliang Chen; Jianqiang Li; Li Zhang; Zahir Tari; Wei-Tao Xu | G4: 2024 | H4: IEEE Internet of Things Journal | I4: 10.1109/jiot.2024.3439194 | K4: Journal article (original research) | L4: English (automatically detected) | M4: Preventive dentistry / dental public health | N4: Semantic Scholar | O4: EXCLUDE | P4: E2 | Q4: wearable toothbrushing sensing system; LLM only feedback add-on | R4: EXCLUDE | S4: E2 | T4: wearable toothbrushing sensing system; LLM only add-on feedback | U4: =IF(AND(O4=R4,O4<>"UNSURE"),"Agree","Conflict/Unsure") -> Agree | Y4: 0.079 | Z4: 1862 | AA4: No | AD4: EXCLUDE | AE4: E2 | AF4: R1 = R2
A5: LLMDENT-1406 | B5: 4 | C5: calibration | D5: SPECTRUM SRA: An R Shiny Application to Automate Systematic Reviews Using Artificial Intelligence and Large Language Models | E5: Abstract Purpose : This study aims to develop an R Shiny application named SPECTRUM SRA (Systematic Review Automation) and to assess its feasibility. The application encompasses eight modules: Search, PRISMA flow diagram generation, dEduplication, sCreening, daTa extraction, Reporting, qUery, and suMmarization. It provides an end‑to‑end workflow to automate and semi‑automate multiple steps of systematic reviews, addressing growing time and labor constraints and accelerating evidence‑to‑practice translation. Design/methodology/approach : SPECTRUM SRA comprises eight interconnected modules and offers an interface for automated article search and retrieval from PubMed, Scopus, and Web of Science. Search functionality is implemented via API integration for PubMed and Scopus, with manual search and import for Web of Science results. Deduplication employs two strategies: DOI‑based matching and fuzzy string deduplication. The application also supports automated title/abstract and full‑text screening using large language model prompting. Automated reporting for both search and screening is incorporated through AI‑driven scripting. Additionally, SPECTRUM SRA automates PRISMA flow diagram generation. Summarization and data extraction of the final set of eligible studies are performed via LLM prompting. The feasibility of the application was assessed through a systematic review of randomized controlled trials comparing virtual reality interventions to non‑virtual‑reality approaches in d… | F5: Nezhad HM; CheshmehSohrabi M | G5: 2025 | H5: Research Square | I5: 10.21203/rs.3.rs-7265470/v1 | K5: Preprint | L5: English (automatically detected) | M5: Oral & maxillofacial surgery | N5: Europe PMC (Preprint) | O5: EXCLUDE | P5: E2 | Q5: LLM as systematic review automation tool | R5: EXCLUDE | S5: E2 | T5: LLM as systematic review automation research tool | U5: =IF(AND(O5=R5,O5<>"UNSURE"),"Agree","Conflict/Unsure") -> Agree | Y5: 0.02 | Z5: 2052 | AA5: No | AD5: EXCLUDE | AE5: E2 | AF5: R1 = R2
A6: LLMDENT-2157 | B6: 5 | C6: calibration | D6: Perplexity and Repercussions in Maldiagnosis of an Extraoral Draining Sinus by a Physician and its Dental Management: A Case Report. | E6: UNLABELLED: The cutaneous sinus of dental origin represents a skin disorder that appears due to an infection accompanied by bony changes. The remote location of the lesion relative to the primary site of the disease leads to its presumption of a skin etiology by the individual. Inadequate knowledge on the part of the physician followed by faulty management complicates the situation further. However, unless the dental cause is not addressed, the lesion does not resolve. The following case report discusses the dental management of an extraoral sinus with the aim of guiding the general public, physicians, and dentists with its accurate and timely assessment so as to avoid additional financial costs, futile antibiotic therapy courses, and unnecessary surgical excisions. HOW TO CITE THIS ARTICLE: Sidhu S, Thomas AM, Kundra R. Perplexity and Repercussions in Maldiagnosis of an Extraoral Draining Sinus by a Physician and its Dental Management: A Case Report. Int J Clin Pediatr Dent 2022;15(1):115-118. | F6: Sidhu, Seerat; Thomas, Abi M; Kundra, Ruchika | G6: 2022 | H6: International journal of clinical pediatric dentistry | I6: 10.5005/jp-journals-10005-2349 | J6: 35528484.0 | K6: Journal article (original research) | L6: English | M6: Dental pharmacology / anesthesia | N6: Crossref; Europe PMC; PubMed/MEDLINE; Semantic Scholar | O6: EXCLUDE | P6: E2 | Q6: case report; no LLM | R6: EXCLUDE | S6: E2 | T6: clinical case report; no LLM | U6: =IF(AND(O6=R6,O6<>"UNSURE"),"Agree","Conflict/Unsure") -> Agree | Y6: 0.136 | Z6: 1576 | AA6: No | AD6: EXCLUDE | AE6: E2 | AF6: R1 = R2
A7: LLMDENT-0625 | B7: 6 | C7: calibration | D7: A cross-sectional evaluation of Large Language Model answers to dental questions. | E7: BACKGROUND: Patients increasingly turn to the Internet and, more recently, to Large Language Models (LLMs) to seek answers to dental questions. However, the safety of LLM-generated dental advice for patients has not been systematically assessed. METHODS: Thirty dental questions spanning six disciplines were developed and posed in Polish and English to six LLMs. Each question was answered five times per model per language, yielding 2,700 unique LLM-generated answers, each independently evaluated by two dentists. A binary text classifier combining Qwen3-Embedding-0.6B word embeddings with a Support Vector Machine (SVM) was trained on 1,680 labeled answers and evaluated on 420 held-out answers. RESULTS: Substantial inter-rater agreement on harmfulness was observed (Cohen's [Formula: see text]). Without a system prompt, 56% of outputs from gpt-4o, gpt-4o-mini, and llama-3.3-70b were classified as harmful (pooling both languages; a question was counted as harmful if at least one of its five generated answers was labeled harmful by at least one annotator). A safety-oriented system prompt reduced this rate by 26 percentage points to 30%. llama-3.3-70b showed markedly higher harmfulness in Polish than English ([Formula: see text], [Formula: see text]). The trained classifier showed a tendency to mark non-harmful answers as harmful, though performance was lower for Polish than English outputs. CONCLUSIONS: Publicly available LLMs can pose potential safety risks to dental patients when… | F7: Mysior, Martyna; Mysior, Marek Piotr; Maslowski, Pamela; Skośkiewicz-Malinowska, Katarzyna | G7: 2026 | H7: BMC oral health | I7: 10.1186/s12903-026-09223-4 | J7: 42432645.0 | K7: Journal article (original research) | L7: English | M7: General dentistry / cross-specialty | N7: Amass BiomedCore (connector); Crossref; Europe PMC; PubMed/MEDLINE; Semantic Scholar | O7: INCLUDE | P7: - | Q7: dental advice for patients; six LLMs; harmfulness rated by dentists | R7: INCLUDE | S7: - | T7: patient dental questions; six LLMs; harmfulness rated by dentists | U7: =IF(AND(O7=R7,O7<>"UNSURE"),"Agree","Conflict/Unsure") -> Agree | Y7: 0.421 | Z7: 589 | AA7: No | AD7: INCLUDE | AE7: - | AF7: R1 = R2
A8: LLMDENT-1105 | B8: 7 | C8: calibration | D8: Accuracy of Artificial Intelligence in Making Diagnoses and Treatment Decisions in Pediatric Dentistry. | E8: Purpose: To assess the diagnostic and treatment decision-making accuracy of ChatGPT for various dental problems in pediatric patients compared to specialized pediatric dentists. Methods: This study included 12 cases, each with an average of three dental problems, resulting in a total of 36 dental problems. Successive prompts were given to ChatGPT (GPT-4), beginning with a comprehensive case presentation, followed by clinical and radiographic descriptions alongside clinical and radiographic images. Inputs for questions regarding the diagnosis and treatment were provided to the models. Accuracy was then scored based on the degree of alignment between the ChatGPT outputs and the pediatric dentistry committee decisions, which represented the control group based on their advanced training and clinical experience. Results: ChatGPT's diagnostic accuracy was 72.2 percent, with a kappa statistic of 0.69 (95 percent confidence interval [95% CI] equals 0.6 to 0.8). In detecting dental caries, ChatGPT achieved a sensitivity of 92.3 percent and a specificity of 100 percent, with positive and negative predictive values of 100 percent and 83.3 percent, respectively. ChatGPT's treatment decision accuracy was 47.2 percent with a kappa value of 0.43 (95% CI equals 0.4 to 0.6). The difference between the accuracy of ChatGPT in diagnosis and treatment decisions was statistically significant (P=0.01). Conclusions: ChatGPT achieved high diagnostic accuracy but had limited capability in making trea… | F8: Bhadila, Ghalia Y; Alhomied, Mody; Mahmoud, Abeer; Farsi, Nada J | G8: 2025 | H8: Pediatric dentistry | J8: 40296263.0 | K8: Journal article (original research) | L8: English | M8: Pediatric dentistry; Restorative dentistry / cariology; Oral & maxillofacial radiology | N8: Europe PMC; PubMed/MEDLINE; Semantic Scholar | O8: EXCLUDE | P8: E3 | Q8: GPT-4 diagnosis/treatment decisions pediatric cases with images | R8: EXCLUDE | S8: E3 | T8: pediatric case diagnosis/treatment decisions with images | U8: =IF(AND(O8=R8,O8<>"UNSURE"),"Agree","Conflict/Unsure") -> Agree | Y8: 0.299 | Z8: 873 | AA8: No | AD8: EXCLUDE | AE8: E3 | AF8: R1 = R2
A9: LLMDENT-0972 | B9: 8 | C9: calibration | D9: Author Correction: Towards clinical-level interpretation of dental panoramic radiography using an instance-guided vision-language model. | F9: Zhu, Qikui; Lin, Yeyu; Fu, Weitao; Tang, Wenhui; Li, Jiaxing; Zhang, Ying; Li, Bo; Guo, Xiaolong; Wang, Fang; Qi, Haiyan; Sun, Chongke; Zhu, Xiangkui; Liu, Zhonghao; He, Li; Zheng, Zhiguo; Du, Bo; Yan | G9: 2026 | H9: Nature biomedical engineering | I9: 10.1038/s41551-026-01759-8 | J9: 42420428.0 | K9: Erratum / correction | L9: English | M9: Oral & maxillofacial radiology | N9: Europe PMC; PubMed/MEDLINE; Semantic Scholar | O9: EXCLUDE | P9: E2 | Q9: erratum; custom vision-language model panoramic radiographs | R9: EXCLUDE | S9: E2 | T9: erratum; dental radiograph vision-language model | U9: =IF(AND(O9=R9,O9<>"UNSURE"),"Agree","Conflict/Unsure") -> Agree | Y9: 0.053 | Z9: 1960 | AA9: No | AD9: EXCLUDE | AE9: E2 | AF9: R1 = R2
A10: LLMDENT-0959 | B10: 9 | C10: calibration | D10: SegORG: Report Generation of Oral Potentially Malignant Disorders Image Based on Lesion Segmentation-Enhanced LLM. | E10: OBJECTIVES: To develop an automated system for generating standardized reports for oral potentially malignant disorders (OPMDs) from white-light images, aiming to reduce documentation workload, facilitate early intervention, and enable longitudinal lesion monitoring. METHODS: We proposed the SegORG model using 441 oral mucosa images and 1323 corresponding reports. It employed SegFormer for lesion segmentation; a visual encoder extracted global and local visual embeddings, which were projected into a pre-trained large language model (LLM feature) space via a lightweight visual mapper. The Qwen2.5-7B model then generated structured diagnostic reports, enhanced by text augmentation techniques to improve diversity and professionalism. RESULTS: SegORG achieved BLEU-4, ROUGE-L, and CIDEr scores of 0.291, 0.517, and 0.578, respectively. Additionally, the model obtained a clinical diagnostic F1-score of 0.695 and a median expert rating of 4 on the Likert scale (p < 0.001). It significantly outperformed conventional baseline models (R2Gen, METransformer, and SwinB+BERT9k) and contemporary general-purpose multimodal LLMs (GPT-4, Gemini 2.5 Pro, and Qwen2.5-VL), despite its lean architecture (90.4 M trainable parameters). CONCLUSIONS: By enhancing visual feature extraction and achieving efficient text alignment, SegORG offers an effective technical pathway for OPMDs reports automation. While single-center validation shows promise, multicenter trials are needed to assess generalizability… | F10: Zhang, Rui; Huang, Peng; Ding, Tingting; Chen, Yaowu; Tian, Xiang; Cao, Yuqi; Chen, Wei; Chen, Xiaoyan; Chen, Qianming; Zhu, Fudong | G10: 2026 | H10: Oral diseases | I10: 10.1111/odi.70148 | J10: 41313616.0 | K10: Journal article (original research) | L10: English | M10: Oral & maxillofacial surgery; Oral medicine / oral pathology | N10: Europe PMC; PubMed/MEDLINE | O10: EXCLUDE | P10: E3 | Q10: OPMD image report generation; diagnostic task | R10: EXCLUDE | S10: E3 | T10: image-based OPMD report generation; diagnostic/documentation task | U10: =IF(AND(O10=R10,O10<>"UNSURE"),"Agree","Conflict/Unsure") -> Agree | Y10: 0.16 | Z10: 1444 | AA10: No | AD10: EXCLUDE | AE10: E3 | AF10: R1 = R2
A11: LLMDENT-0968 | B11: 10 | C11: calibration | D11: High-Fidelity and Lip-Synced Talking Face Synthesis via Landmark-Based Diffusion Model. | E11: Audio-driven talking face video generation has attracted increasing attention due to its huge industrial potential. Some previous methods focus on learning a direct mapping from audio to visual content. Despite progress, they often struggle with the ambiguity of the mapping process, leading to flawed results. An alternative strategy involves facial structural representations (e.g., facial landmarks) as intermediaries. This multi-stage approach better preserves the appearance details but suffers from error accumulation due to the independent optimization of different stages. Moreover, most previous methods rely on generative adversarial networks, prone to training instability and mode collapse. To address these challenges, our study proposes a novel landmark-based diffusion model for talking face generation, which leverages facial landmarks as intermediate representations while enabling end-to-end optimization. Specifically, we first establish the less ambiguous mapping from audio to landmark motion of lip and jaw. Then, we introduce an innovative conditioning module called TalkFormer to align the synthesized motion with the motion represented by landmarks via differentiable cross-attention, which enables end-to-end optimization for improved lip synchronization. Besides, TalkFormer employs implicit feature warping to align the reference image features with the target motion for preserving more appearance details. Extensive experiments demonstrate that our approach can synthesi… | F11: Zhong, Weizhi; Lin, Junfan; Chen, Peixin; Gao, Feng; Lin, Liang; Li, Guanbin | G11: 2026 | H11: IEEE transactions on image processing : a publication of the IEEE Signal Processing Society | I11: 10.1109/tip.2026.3676251 | J11: 41886322.0 | K11: Journal article (original research) | L11: English | M11: General dentistry / cross-specialty | N11: Europe PMC; PubMed/MEDLINE | O11: EXCLUDE | P11: E1 | Q11: talking face video synthesis; not dental | R11: EXCLUDE | S11: E1 | T11: talking face video synthesis; not dental | U11: =IF(AND(O11=R11,O11<>"UNSURE"),"Agree","Conflict/Unsure") -> Agree | Y11: 0.003 | Z11: 2090 | AA11: No | AD11: EXCLUDE | AE11: E1 | AF11: R1 = R2
A12: LLMDENT-1607 | B12: 11 | C12: calibration | D12: ProtBERT-Based Prediction of Functional TRPV Sequences for Oral Cancer Pain | E12: Background and Objectives: Oral Cancer often leads to opioid tolerance, affecting pain-sensing neurons. TRPV ion channels, which are activated by inflammatory molecules, can be agonists or antagonists. Cancer changes the peripheral and central nervous systems, affecting tumor interactions, nociceptors, and the immune system. Activation of these receptors triggers pain perception and second messengers. Antagonists alleviate cancer-induced pain, suggesting therapeutic approaches. This study uses a large language model to find and forecast functional TRPV sequences for oral cancer pain. Materials and Methods: TRPV proteins were obtained from UniProt; id -Q8NER1, Q9HBA0, Q9NQA5, Q9H1D0, and Q9Y5S1 were identified and quality-checked. Deepbio analyzed FASTA sequences. Large language models and sequence prediction techniques were used for prediction and classification, including Protbert (a pre-trained protein sequence model), BiLSTM, LSTMAttention, and TextRGNN (a residual graph neural network). Results: The study reveals that ProtBERT and BiLSTM are the best predictors of amino acid sequences for TRPV1-based oral cancer, offering a balance of sensitivity and specificity. The ProtBERT model effectively identifies positive and negative cases related to TRPV with an accuracy of 0.90, a sensitivity of 0.89, a specificity of 0.91, and an AUC of 0.937. The BiLSTM model, similar to ProtBERT, has high accuracy and sensitivity, while the LSTM Attention model is reliable in detecting true … | F12: P. Yadalam | G12: 2025 | H12: The Journal of Basic and Clinical Dentistry | I12: 10.64471/30rcas82 | K12: Journal article (original research) | L12: English (automatically detected) | M12: Oral medicine / oral pathology | N12: Semantic Scholar | O12: EXCLUDE | P12: E2 | Q12: ProtBERT protein sequence prediction; not chatbot | R12: EXCLUDE | S12: E2 | T12: ProtBERT protein sequence prediction; not chatbot | U12: =IF(AND(O12=R12,O12<>"UNSURE"),"Agree","Conflict/Unsure") -> Agree | Y12: 0.183 | Z12: 1338 | AA12: No | AD12: EXCLUDE | AE12: E2 | AF12: R1 = R2
A13: LLMDENT-0316 | B13: 12 | C13: calibration | D13: From reviews to real-time: dynamic evidence in dentistry. | E13: BACKGROUND: The exponential growth of biomedical literature-over a million new PubMed entries each year-has outpaced traditional evidence-synthesis methods. Systematic reviews, long the cornerstone of evidence-based dentistry, are resource-intensive and often outdated within a few years, widening the gap between current research and clinical practice. METHODS: We outline Retrieval-Augmented Generation (RAG) as a methodology for dynamic evidence reviews. RAG strengthens Large Language Models (LLMs) by combining their generative capacity with real-time retrieval from a continuously updated, curated knowledge base. This design grounds every answer in verifiable sources and mitigates the factual errors and hallucinations seen in standalone LLMs. RESULTS/IMPLICATIONS: RAG enables on-demand dynamic synthesis of the latest evidence, allowing clinicians and researchers to ask complex, natural-language questions and receive concise, fully cited answers. For dental clinicians, this approach enables rapid, citation-linked answers to practice-relevant questions-such as material selection, healing outcomes, or procedural comparisons-without relying on outdated narrative summaries. We describe three complementary integration pathways-RAG on pre-retrieved article pools, public living review portals, and machine-actionable journal publications-each with distinct requirements and benefits. Looking forward, emerging agentic AI systems, capable of planning multi-step searches and iterative upda… | F13: Gavrilova, A V; Galli, C | G13: 2026 | H13: Evidence-based dentistry | I13: 10.1038/s41432-026-01206-2 | J13: 41735601.0 | K13: Journal article (original research) | L13: English | M13: General dentistry / cross-specialty | N13: Europe PMC; PubMed/MEDLINE; Semantic Scholar | O13: EXCLUDE | P13: E2 | Q13: RAG methodology for evidence synthesis; conceptual; clinicians/researchers | R13: EXCLUDE | S13: E2 | T13: conceptual RAG framework for evidence synthesis; no chatbot evaluation | U13: =IF(AND(O13=R13,O13<>"UNSURE"),"Agree","Conflict/Unsure") -> Agree | Y13: 0.045 | Z13: 1981 | AA13: No | AD13: EXCLUDE | AE13: E2 | AF13: R1 = R2
A14: LLMDENT-0500 | B14: 13 | C14: calibration | D14: Evaluation of large language models in root resorption scenarios: an ESE-aligned comparative performance assessment. | E14: This study aims to compare the diagnostic accuracy, appropriateness of treatment planning, and source citation performance of five large language models ChatGPT-4o (Free), ChatGPT-5.1 Plus, Microsoft Copilot, Google Gemini, and DeepSeek-R1 in root resorption scenarios. In December 2025, twelve clinical scenarios were created based on the classification of the European Society of Endodontology and each scenario was presented to all chatbots over four consecutive days. All responses were evaluated using a blinded assessment protocol and a binary scoring system. A total of 720 observations (12 cases × 4 repetitions × 3 criteria per model) were analyzed. The collected data were analyzed using chi-square, Fisher's exact, and Cochran Q tests. In terms of diagnostic accuracy, Microsoft Copilot (79.2%), ChatGPT-5.1 (77.1%), and ChatGPT-4o (Free) (75%) showed the highest performance. Google Gemini (68.8%) demonstrated a moderate level of accuracy, while DeepSeek (39.6%) showed markedly low performance. All models exhibited high accuracy in treatment plan recommendations, and no statistically significant differences were detected. Regarding citation accuracy, Copilot ranked first with 100% accuracy. Although large language models present potential as supportive decision-making tools in the evaluation of root resorption, diagnostic inconsistencies, limitations in source accuracy, and variability in responses restrict their independent use in clinical applications. Therefore, the outputs… | F14: Keleş, Öznur Küçük; Arslan, Zeynep Betül | G14: 2026 | H14: Odontology | I14: 10.1007/s10266-026-01531-z | J14: 42573919.0 | K14: Journal article (original research) | L14: English | M14: Endodontics | N14: Europe PMC; PubMed/MEDLINE; Semantic Scholar | O14: EXCLUDE | P14: E3 | Q14: root resorption clinical scenarios; diagnosis and treatment planning | R14: EXCLUDE | S14: E3 | T14: root resorption clinical scenarios; diagnosis and treatment planning | U14: =IF(AND(O14=R14,O14<>"UNSURE"),"Agree","Conflict/Unsure") -> Agree | Y14: 0.445 | Z14: 546 | AA14: No | AD14: EXCLUDE | AE14: E3 | AF14: R1 = R2
A15: LLMDENT-1556 | B15: 14 | C15: calibration | D15: Evaluation of artificial intelligence robot's knowledge and reliability on dental implants and peri-implant phenotype. | E15: Abstract The aim of this study was to evaluate the reliability and quality of information generated by ChatGPT regarding dental implants and peri-implant phenotypes. A structured questionnaire on these topics was presented to the AI-based chatbot, and its responses were assessed by dental professionals using a modified Global Quality Scale (GQS) and the DISCERN tool. The study included 60 participants divided into three professional groups: oral and maxillofacial surgeons, periodontologists, and general dental practitioners. While no statistically significant differences were observed among the groups (p > 0.05), oral and maxillofacial surgeons consistently assigned lower DISCERN and GQS scores compared to other professionals. The findings of this study suggest that ChatGPT has the potential to serve as a supplementary tool for patient information in dental implant procedures. However, its responses may lack the depth and specificity required for clinical decision-making. Dental professionals should exercise caution when relying on artificial intelligence (AI) -generated content and guide patients in interpreting such information. Future research should explore the variability of AI responses, assess multiple chatbot platforms, and investigate their integration into dental clinical practice. | F15: Terzi, Mithat; Yavuz, Mustafa Cihan; Bicer, Tayyip; Buyuk, S Kutalmış | G15: 2025 | H15: Scientific reports | I15: 10.1038/s41598-025-94576-z | J15: 40108433.0 | K15: Journal article (original research) | L15: English | M15: Periodontology; Implant dentistry; Oral & maxillofacial surgery | N15: Amass BiomedCore (connector); DOAJ; Europe PMC; PubMed/MEDLINE; Semantic Scholar | O15: INCLUDE | P15: - | Q15: ChatGPT implants/peri-implant phenotype; GQS DISCERN; patient info potential | R15: INCLUDE | S15: - | T15: ChatGPT implant info; GQS and DISCERN by professionals; patient info | U15: =IF(AND(O15=R15,O15<>"UNSURE"),"Agree","Conflict/Unsure") -> Agree | Y15: 0.764 | Z15: 255 | AA15: No | AD15: INCLUDE | AE15: - | AF15: R1 = R2
A16: LLMDENT-0639 | B16: 15 | C16: calibration | D16: Integrating ChatGPT into Dental Education: Perceptions, Ethical Challenges, and Curriculum Development Implications | E16: Introduction: This preliminary investigation examined how the dental community views the incorporation of ChatGPT into the dental education curriculum and research. This research seeks to investigate how participants perceive, feel about, and prefer the potential use of ChatGPT to enhance teaching, learning, and research activities in dental education. Methods: A cross-sectional questionnaire was administered to 148 participants (37 staff and 111 students). The survey gathered data on the participants’ knowledge of ChatGPT, their views on its potential educational impact, and their preferences for integrating ChatGPT into the dental curriculum. Statistical analysis was performed to evaluate differences based on demographic and academic factors. Results: The study found that 47.3% of the participants demonstrated a good understanding of ChatGPT basics, with 52.7% recognizing its limitations in terms of education and research. The majority (66%) believed that ChatGPT would significantly influence dental education within two years. Despite positive attitudes towards its potential, 80.4% of the participants emphasized the need for careful management and control of ChatGPT. Less than 40% preferred personalized feedback from ChatGPT, with many participants highlighting the necessity for additional guidance and skill development to use the tool efficiently. Conclusion: The findings suggest that ChatGPT holds considerable promise in enhancing dental education. However, apprehensions … | F16: Sangeetha Narasimhan; Mohamed El-Kishawi; Sausan Al Kawas; Marwan Mansoor Mohammed; V. Kamath; S. Shetty | G16: 2026 | H16: Dubai Medical Journal | I16: 10.18502/dmj.v9is1.21025 | K16: Review (narrative) | L16: English (automatically detected) | M16: Preventive dentistry / dental public health; Dental education / exams | N16: DOAJ; Semantic Scholar | O16: EXCLUDE | P16: E3 | Q16: questionnaire on ChatGPT in dental education | R16: EXCLUDE | S16: E3 | T16: dental education perception questionnaire | U16: =IF(AND(O16=R16,O16<>"UNSURE"),"Agree","Conflict/Unsure") -> Agree | Y16: 0.018 | Z16: 2061 | AA16: No | AD16: EXCLUDE | AE16: E3 | AF16: R1 = R2
A17: LLMDENT-1964 | B17: 16 | C17: calibration | D17: Unlocking the Potentials of Large Language Models in Orthodontics: A Scoping Review. | E17: (1) Background: In recent years, large language models (LLMs) such as ChatGPT have gained significant attention in various fields, including dentistry. This scoping review aims to examine the current applications and explore potential uses of LLMs in the orthodontic domain, shedding light on how they might improve dental healthcare. (2) Methods: We carried out a comprehensive search in five electronic databases, namely PubMed, Scopus, Embase, ProQuest and Web of Science. Two authors independently screened articles and performed data extraction according to the eligibility criteria, following the PRISMA-ScR guideline. The main findings from the included articles were synthesized and analyzed in a narrative way. (3) Results: A total of 706 articles were searched, and 12 papers were eventually included. The applications of LLMs include improving diagnostic and treatment efficiency in orthodontics as well as enhancing communication with patients. (4) Conclusions: There is emerging research in countries worldwide on the use of LLMs in orthodontics, suggesting an upward trend in their acceptance within this field. However, the potential application of LLMs remains in its early stage, with a noticeable lack of extensive studies and tailored products to address specific clinical needs. | F17: Zheng, Jie; Ding, Xiaoqian; Pu, Jingya Jane; Chung, Sze Man; Ai, Qi Yong H; Hung, Kuo Feng; Shan, Zhiyi | G17: 2024 | H17: Bioengineering (Basel, Switzerland) | I17: 10.3390/bioengineering11111145 | J17: 39593805.0 | K17: Systematic / scoping review | L17: English | M17: Orthodontics; Oral & maxillofacial surgery | N17: Amass BiomedCore (connector); DOAJ; Europe PMC; PubMed/MEDLINE; Semantic Scholar | O17: EXCLUDE | P17: E5 | Q17: scoping review LLMs orthodontics | R17: EXCLUDE | S17: E5 | T17: scoping review LLMs orthodontics | U17: =IF(AND(O17=R17,O17<>"UNSURE"),"Agree","Conflict/Unsure") -> Agree | Y17: 0.037 | Z17: 2010 | AA17: No | AD17: EXCLUDE | AE17: E5 | AF17: R1 = R2
A18: LLMDENT-1346 | B18: 17 | C18: calibration | D18: Evaluating the quality and empathy of responses to patient questions on the Korean Academy of Periodontology's online question and answer section: a cross-sectional study comparing periodontists and an AI-powered chatbot. | E18: PURPOSE: This study aimed to evaluate and compare the responses of an artificial intelligence (AI)-powered chatbot and professional periodontists to patient queries in periodontology and implantology, using the Korean Academy of Periodontology's (KAP) online question and answer (Q&A) section. METHODS: In this comparative cross-sectional study, we analyzed 219 patient-submitted periodontal and implant knowledge questions from the KAP online Q&A section. A panel of 10 evaluators-5 periodontists and 5 laypersons-rated both the periodontist's and the AI chatbot's responses using standardized scales. We applied the t-test and Spearman correlation coefficients to compare response quality, empathy, consistency, and evaluator preferences. RESULTS: Ten evaluators judged the AI chatbot's responses to be significantly superior in quality and empathy compared to periodontist replies. A higher proportion of periodontist responses fell below acceptable quality ("very poor" or "poor") than chatbot responses (28.7% vs. 15.0%; P<0.001), and more chatbot replies were rated "empathetic" or "very empathetic" (62.5% vs. 42.8%; P<0.001). Overall response consistency was deemed satisfactory at 64.2%, with no significant difference in consistency or preference between periodontist and lay evaluators. CONCLUSIONS: AI-powered chatbots can deliver more accurate and empathetic answers than human periodontists, suggesting their potential role as consultation assistants merits further investigation. The h… | F18: Lee, Jae-Hong; Oh, So-Hae; Schwendicke, Falk; Chaurasia, Akhilanand; Kim, Young-Taek | G18: 2025 | H18: Journal of periodontal & implant science | I18: 10.5051/jpis.2402220111 | J18: 40501075.0 | K18: Journal article (original research) | L18: English | M18: Periodontology; Implant dentistry | N18: Crossref; Europe PMC; PubMed/MEDLINE; Semantic Scholar | O18: INCLUDE | P18: - | Q18: patient questions KAP Q&A; chatbot vs periodontists; quality empathy | R18: INCLUDE | S18: - | T18: KAP patient Q&A periodontology; chatbot vs periodontists; quality rated | U18: =IF(AND(O18=R18,O18<>"UNSURE"),"Agree","Conflict/Unsure") -> Agree | Y18: 0.764 | Z18: 256 | AA18: No | AD18: INCLUDE | AE18: - | AF18: R1 = R2
A19: LLMDENT-1364 | B19: 18 | C19: calibration | D19: Accuracy and reliability of Manus, ChatGPT, and Claude in case-based dental diagnosis. | E19: INTRODUCTION: Artificial intelligence (AI), particularly large language models (LLMs), is transforming healthcare education and clinical decision-making. While models like ChatGPT and Claude have demonstrated utility in medical contexts, their performance in dental diagnostics remains underexplored; additionally, the potential of emerging platforms, like Manus, is yet to be evaluated. OBJECTIVE: To compare the diagnostic accuracy and consistency of the ChatGPT, Claude, and Manus-using authentic, case-based dental scenarios. METHODS: A set of 117 multiple-choice questions based on validated clinical dental vignettes spanning various specialities was administered to each model under standardised conditions at two separate time points. Responses were scored against expert-validated answer keys. Inter-rater reliability was assessed using Cohen's kappa, and statistical comparisons were made using the chi-square, McNemar, and t-tests. RESULTS: Claude and Manus consistently outperformed ChatGPT across both testing phases. In the second round, Claude and Manus achieved a diagnostic accuracy of 92.3%, compared to ChatGPT's 76.9%. Claude and Manus also demonstrated higher intra-model consistency (Cohen's kappa = 0.714 and 0.782, respectively) than ChatGPT (kappa = 0.560). Although the numerical trends favoured Claude and Manus, pairwise differences in accuracy did not reach statistical significance. CONCLUSION: Claude and Manus demonstrated numerically higher diagnostic performance and… | F19: Madfa, Ahmed A; Alshammari, Abdullah F; Anazi, Bassam A; Alenezi, Yousef E; Alkurdi, Khlood A | G19: 2025 | H19: Frontiers in oral health | I19: 10.3389/froh.2025.1686090 | J19: 41584961.0 | K19: Journal article (original research) | L19: English | M19: Dental education / exams; General dentistry / cross-specialty | N19: Amass BiomedCore (connector); Crossref; DOAJ; Europe PMC; PubMed/MEDLINE; Semantic Scholar | O19: EXCLUDE | P19: E3 | Q19: MCQ clinical vignettes diagnostic accuracy | R19: EXCLUDE | S19: E3 | T19: MCQ clinical vignettes diagnostic accuracy | U19: =IF(AND(O19=R19,O19<>"UNSURE"),"Agree","Conflict/Unsure") -> Agree | Y19: 0.318 | Z19: 816 | AA19: No | AD19: EXCLUDE | AE19: E3 | AF19: R1 = R2
A20: LLMDENT-0239 | B20: 19 | C20: calibration | D20: Comment on "Diagnostic Performance of Multimodal Large Language Models in the Analysis of Oral Pathology". | E20: The data that support the findings of this study are available from the corresponding author, Hinpetch Daungsupawong, upon reasonable request. | F20: Daungsupawong, Hinpetch; Wiwanitkit, Viroj | G20: 2026 | H20: Oral diseases | I20: 10.1111/odi.70055 | J20: 40760938.0 | K20: Letter / comment / editorial | L20: English | M20: Oral medicine / oral pathology | N20: Europe PMC; PubMed/MEDLINE; Semantic Scholar | O20: EXCLUDE | P20: E3 | Q20: comment on multimodal LLM oral pathology diagnosis | R20: EXCLUDE | S20: E3 | T20: comment on multimodal oral pathology diagnosis; also letter | U20: =IF(AND(O20=R20,O20<>"UNSURE"),"Agree","Conflict/Unsure") -> Agree | Y20: -0.037 | Z20: 2134 | AA20: No | AD20: EXCLUDE | AE20: E3 | AF20: R1 = R2
A21: LLMDENT-0827 | B21: 20 | C21: calibration | D21: Preliminary Evaluation of Large Language Models in Kennedy Classification and Removable Partial Denture Planning: An In Silico Study. | E21: BACKGROUND This study evaluated text-based large language models for Kennedy classification and removable partial denture planning in partially edentulous cases, where comparative evidence on accuracy remains limited. MATERIAL AND METHODS Twenty-six partially edentulous cases, defined according to the Federation Dentaire Internationale tooth numbering system and classified as Kennedy Classes I to IV, were included. Case scenarios were constructed by an experienced prosthodontist. Questions were independently submitted to 4 large language models without prior training or prompting: ChatGPT-5.2, Claude Sonnet 4.6, Gemini 3 Flash, and Perplexity. Responses were evaluated by 2 independent prosthodontists (different from the case developer) - blinded to the identity of each model - using predefined criteria for Kennedy classification accuracy and prosthetic planning consistency. Statistical analyses included intergroup comparisons and effect size estimation. RESULTS Statistically significant differences were identified among the models in both tasks (P<0.001). For Kennedy classification, the effect size was moderate (Kendall's W=0.402). Gemini 3 Flash achieved the highest mean score, followed by ChatGPT-5.2, Perplexity, and Claude Sonnet 4.6. Similarly, significant differences were observed in removable partial denture planning performance (Kendall's W=0.424); Gemini 3 Flash scored significantly higher than the other models (P≤0.001). CONCLUSIONS Large language models showed varia… | F21: Sümer Ekin, Ebru; Değer, Yalçın; Dündar Yilmaz, Berivan; Yildiz, İsmail | G21: 2026 | H21: Medical science monitor : international medical journal of experimental and clinical research | I21: 10.12659/msm.953353 | J21: 42093138.0 | K21: Journal article (original research) | L21: English | M21: Prosthodontics | N21: Europe PMC; PubMed/MEDLINE; Semantic Scholar | O21: EXCLUDE | P21: E3 | Q21: Kennedy classification and RPD planning for clinicians | R21: EXCLUDE | S21: E3 | T21: Kennedy classification and RPD planning cases for clinicians | U21: =IF(AND(O21=R21,O21<>"UNSURE"),"Agree","Conflict/Unsure") -> Agree | Y21: 0.447 | Z21: 541 | AA21: No | AD21: EXCLUDE | AE21: E3 | AF21: R1 = R2
A22: LLMDENT-0367 | B22: 21 | C22: calibration | D22: Psychological Inclinations and Practical Utility of ChatGPT Among Undergraduate Dental Students at a Dental School in Karachi: A Cross-Sectional Observational Study. | E22: ABSTRACT Objectives This study aims to explore the correlation of psychological domains and behavioural engagement with ChatGPT among undergraduate dental students. Material and Methods A cross‐sectional study was conducted using a self‐administered questionnaire (supporting material) distributed to 130 undergraduate dental students of a dental school in Karachi, Pakistan. The questionnaire assessed the frequency and purpose of ChatGPT usage across academic domains and specific learning contexts. It also evaluated students’ attitudes, perceptions, and behaviors using a Likert scale. Descriptive statistics were used for analysis, while Spearman's correlation tests were applied to examine subgroup differences and relationships between attitudes and behaviors. Results Most participants reported learning about ChatGPT through peers or friends (n = 53) and social media (n = 38). The mean composite scores for the psychological domains [Perception(3.27), behaviour (3.21) and Attitude (3.19)] indicate a generally neutral‐to‐moderately positive inclination toward ChatGPT. The primary area of usage was basic dental sciences (n = 73). A strong positive correlation was observed between trust in ChatGPT for dental explanations and behavioral engagement (rs = 0.86, 95% CI [0.88, 0.95], p = 0.003, Holm–Bonferroni adjusted p = 0.006), while doubts regarding its accuracy were negatively correlated with engagement (rs = −0.91, 95% CI [−0.97, −0.76], p = 0.002, adjusted p = 0.006). Students who… | F22: Hanif, Ayesha; Gul, Amna; Maqsood, Afsheen; Naeem, Marium; Shahid, Rumaisa; Abbasi, Maria Shakoor; Ahmed, Naseer; Heboyan, Artak | G22: 2026 | H22: Health science reports | I22: 10.1002/hsr2.71808 | J22: 41694212.0 | K22: Journal article (original research) | L22: English | M22: Dental education / exams; General dentistry / cross-specialty | N22: Crossref; DOAJ; Europe PMC; PubMed/MEDLINE; Semantic Scholar | O22: EXCLUDE | P22: E3 | Q22: dental student survey on ChatGPT use | R22: EXCLUDE | S22: E3 | T22: dental student ChatGPT usage/attitude questionnaire | U22: =IF(AND(O22=R22,O22<>"UNSURE"),"Agree","Conflict/Unsure") -> Agree | Y22: 0.184 | Z22: 1330 | AA22: No | AD22: EXCLUDE | AE22: E3 | AF22: R1 = R2
A23: LLMDENT-0417 | B23: 22 | C23: calibration | D23: Can Large Language Models Support Endodontic Decision-Making? Accuracy and Consistency of ChatGPT and Gemini in Deep Caries and Pulp Exposure | E23: Background: This study evaluated the accuracy and consistency of responses generated by 2 large language models (LLMs), ChatGPT and Gemini, regarding the management of deep carious lesions and pulp exposure in endodontics. Methods: Fifty dichotomous (Yes/No) questions were developed based on the position statement of the European Society of Endodontology and distributed across 5 categories: Diagnosis and Classification, Caries Management, Pulp Exposure Management, Materials and Techniques, and Follow-up and Prognosis. Questions were presented to ChatGPT-4o and Gemini (Flash 2.5) on 3 occasions, 1 week apart. A total of 300 responses were collected and compared with reference answers. Accuracy was measured as the proportion of correct responses, while consistency was assessed using Fleiss’ Kappa across time points. Statistical analyses included Cochran’s Q and McNemar’s test, with significance set at P < .05. Results: ChatGPT achieved an overall accuracy of 76.7%, while Gemini achieved 86.0%, a statistically significant difference favoring Gemini (P=.034). By categories, Gemini showed superior accuracy in Caries Management and Pulp Exposure Management (96.7%), while ChatGPT performed best in Diagnosis and Classification (93.3%). Substantial consistency was observed for both models (Fleiss’ Kappa=0.627 for ChatGPT; 0.723 for Gemini). Gemini’s accuracy varied significantly across weeks (P=.015), whereas ChatGPT’s remained stable (P=.670). Conclusion: Both LLM-based chatbots demo… | F23: Işık, Vasfiye; Şişmanoğlu, Soner; Baybora Kayahan, Mehmet | G23: 2026 | H23: Essentials of Dentistry | I23: 10.5152/essentdent.2026.0113 | K23: Journal article (original research) | L23: English (automatically detected) | M23: Endodontics; Restorative dentistry / cariology | N23: Crossref; DOAJ; Semantic Scholar | O23: EXCLUDE | P23: E3 | Q23: yes/no questions on ESE position statement; clinician decision support | R23: EXCLUDE | S23: E3 | T23: ESE position statement yes/no questions; clinical decision-making for dentists | U23: =IF(AND(O23=R23,O23<>"UNSURE"),"Agree","Conflict/Unsure") -> Agree | Y23: 0.448 | Z23: 539 | AA23: No | AD23: EXCLUDE | AE23: E3 | AF23: R1 = R2
A24: LLMDENT-1439 | B24: 23 | C24: calibration | D24: Odontozap: um chatbot para orientar o atendimento de urgências odontológicas no contexto do SUS | E24: Introdução: Muitos pacientes têm dificuldade em identificar se suas queixas odontológicas exigem atendimento de urgência; o que pode impactar negativamente a jornada de cuidado no SUS. Este trabalho apresenta o desenvolvimento do Odontozap; chatbot criado para orientar pacientes em busca por atendimento odontológico de urgência. A pesquisa adota uma abordagem centrada no usuário envolvendo dentistas e pacientes; com etapas de validação; prototipação e realização de testes de usabilidade. O objetivo é explorar como uma tecnologia interativa pode qualificar e facilitar o acesso a serviços de saúde no contexto do SUS. | F24: L. M. A. Pinheiro; F. Germano; M. D. Gomes; I. Sabóia | G24: 2025 | H24: Anais Estendidos do XXIV Simpósio Brasileiro sobre Fatores Humanos em Sistemas Computacionais (IHC 2025) | I24: 10.5753/ihc_estendido.2025.13252 | K24: Not specified | L24: Portuguese (automatically detected) | M24: General dentistry / cross-specialty | N24: Semantic Scholar | O24: EXCLUDE | P24: E2 | Q24: custom urgent-care chatbot prototype; usability; no general LLM | R24: EXCLUDE | S24: E2 | T24: Odontozap urgency triage chatbot; no general-purpose LLM evident; usability | U24: =IF(AND(O24=R24,O24<>"UNSURE"),"Agree","Conflict/Unsure") -> Agree | Y24: 0.197 | Z24: 1268 | AA24: No | AD24: EXCLUDE | AE24: E2 | AF24: R1 = R2
